<?xml version="1.0"?>
<!-- http://wiki.ros.org/urdf/XML/link -->
<robot name="robot">
    <link name="base_link">
        <visual>
            <origin xyz="0.0 0.0 0.1" rpy="0.0 0.0 0.0"/>
            <geometry>
                <box size="1.0 1.0 0.2"/>
            </geometry>
            <material name="Cyan">
                <color rgba="1.0 1.0 0.0 1.0"/>
            </material>
        </visual>

        <collision>
            <origin xyz="0.0 0.0 0.1" rpy="0.0 0.0 0.0"/>
            <geometry>
                <box size="1.0 1.0 0.2"/>
            </geometry>    
        </collision>
    </link>


    <joint name="joint_1" type="revolute">
        <parent link="base_link"/>
        <child link="first_link"/>
        <origin xyz="0.0 0.0 0.0" rpy="0.0 0.0 0.0"/>
        <axis xyz="0.0 0.0 1.0"/>
        <limit lower="-1.2" upper="1.2" effort="300.0" velocity="2.0"/>
    </joint>

    <link name="first_link">
        <visual name="first_link">
            <origin xyz="0.0 0.0 0.95" rpy="0.0 0.0 0.0"/>
            <geometry>
                <cylinder radius="0.1" length="1.5"/>
            </geometry>
            <material name="red">
                <color rgba="0.0 0.0 1.0 1.0"/>
            </material>
        </visual>
        <collision>
            <origin xyz="0.0 0.0 0.95" rpy="0.0 0.0 0.0"/>
            <geometry>
            <cylinder radius="0.1" length="1.5"/>
            </geometry>
        </collision>

    </link>

    <joint name="joint_2" type="prismatic">
        <parent link="first_link"/>
        <child link="second_link"/>
        <origin xyz="0.0 0.0 1.7" rpy="0.0 0.0 0.0"/>
        <axis xyz="1.0 0.0 0.0"/>
        <limit lower="0.0" upper="1.0" effort="300.0" velocity="2.0"/>
    </joint>

    <link name="second_link">
        <visual name="second_link">
            <origin xyz="0.0 0.0 0.0" rpy="0.0 0.0 0.0"/>
            <geometry>
                <box size="2.0 0.2 0.2"/>
            </geometry>
            <material name="blue">
                <color rgba="0.0 1.0 0.0 1.0"/>
            </material>
        </visual>
    </link>

    <joint name="joint_3" type="prismatic">
        <parent link="second_link"/>
        <child link="third_link"/>
        <origin xyz="0.0 0.0 0.0" rpy="0.0 0.0 0.0"/>
        <axis xyz="0.0 0.0 1.0"/>
        <limit lower="-0.70" upper="0.0" effort="300.0" velocity="2.0"/>
    </joint>

    <link name="third_link">
        <visual name="third_link">
            <origin xyz="1.0 0.0 0.0" rpy="0.0 0.0 0.0"/>
            <geometry>
                <cylinder radius="0.05" length="2.0"/>
            </geometry>
            <material name="yellow">
                <color rgba="1.0 1.0 0.0 1.0"/>
            </material>
        </visual>
    </link>

</robot>
