<?xml version="1.0"?>
<!-- http://wiki.ros.org/urdf/XML/link -->
<robot name="robot">
    <link name="base_link">
        <visual>
            <origin xyz="0.0 0.0 0.0" rpy="0.0 0.0 0.0"/>
            <geometry>
                <box size="0.45 0.45 0.06"/>
            </geometry>
            <material name="red">
                <color rgba="1.0 0.0 0.0 1.0"/>
            </material>
        </visual>

        <collision>
            <origin xyz="0.0 0.0 0.0" rpy="0.0 0.0 0.0"/>
            <geometry>
                <box size="0.45 0.45 0.12"/>
            </geometry>
        </collision>

        <inertial>
            <origin xyz="0.0 0.0 0.0" rpy="0.0 0.0 0.0"/>
            <mass value="1.0"/>
            <inertia ixx="0.0" ixy="0.0" ixz="0.0" iyy="0.0" iyz="0.0" izz="0.0"/>
        </inertial>
    </link>

    <joint name="wheel1_joint" type="continuous">
        <origin xyz="0.225 0.225 0.0" rpy="0.0 0.0 0.0"/>
        <parent link="base_link"/>
        <child link="wheel1_link"/>
        <axis xyz="0.0 0.0 0.0"/>
        <limit effort="300.0" velocity="2.0"/>
    </joint>

    <link name="wheel1_link">
        <visual>
            <origin xyz="0.0 0.0 0.0" rpy="0.0 0.0 0.0"/>
            <geometry>
                <cylinder radius="0.03" length="0.03"/>
            </geometry>
            <material name="blue">
                <color rgba="0.0 0.0 1.0 1.0"/>
            </material>
        </visual>
    </link>


</robot>
